<?xml version="1.0" ?>
<!-- =================================================================================== -->
<!-- |    This document was autogenerated by xacro from romeo_robot.xacro              | -->
<!-- |    EDITING THIS FILE BY HAND IS NOT RECOMMENDED                                 | -->
<!-- =================================================================================== -->
<!--******************************************************************
 ****** File automatically generated by generate_urdf.py script ******
 *********************************************************************-->
<robot name="romeoH37" xmlns:xacro="http://www.ros.org/wiki/xacro">
  <joint name="NeckYaw" type="revolute">
    <parent link="torso"/>
    <child link="NeckYaw_link"/>
    <origin rpy="0 -2.98023e-08 0" xyz="0.0548 0 0.1675"/>
    <axis xyz="0.173651 0 0.984807"/>
    <limit effort="3.662" lower="-2.0595" upper="2.0595" velocity="4.0"/>
  </joint>
  <link name="NeckYaw_link">
    <inertial>
      <mass value="0.32745"/>
      <inertia ixx="0.000242012" ixy="-2.69441e-07" ixz="-1.29328e-05" iyy="0.000225485" iyz="-6.99834e-07" izz="7.29248e-05"/>
      <origin rpy="0 0 0" xyz="-0.00635646 0 -0.030002"/>
    </inertial>
  </link>
  <joint name="NeckPitch" type="revolute">
    <parent link="NeckYaw_link"/>
    <child link="NeckPitch_link"/>
    <origin rpy="0 -2.98023e-08 0" xyz="0 0 0"/>
    <axis xyz="0 1.0 0"/>
    <limit effort="2.978" lower="-0.3142" upper="0.6632" velocity="2.2"/>
  </joint>
  <link name="NeckPitch_link">
    <inertial>
      <mass value="0.29923"/>
      <inertia ixx="0.000412832" ixy="-1.67846e-06" ixz="0.000111721" iyy="0.000383921" iyz="5.04259e-05" izz="0.000264006"/>
      <origin rpy="0 0 0" xyz="0.00372 0 0.04811"/>
    </inertial>
    <visual>
      <geometry>
        <mesh filename="package://romeo_description/meshes/NeckPitch.dae" scale="1 1 1"/>
      </geometry>
      <origin rpy="0 0 0" xyz="0 0 0"/>
    </visual>
    <collision>
      <geometry>
        <mesh filename="package://romeo_description/meshes/NeckPitch_0.10.stl" scale="1 1 1"/>
      </geometry>
      <origin rpy="0 0 0" xyz="0 0 0"/>
    </collision>
  </link>
  <joint name="HeadPitch" type="revolute">
    <parent link="NeckPitch_link"/>
    <child link="HeadPitch_link"/>
    <origin rpy="0 0 0" xyz="0 0 0.0951"/>
    <axis xyz="0 1.0 0"/>
    <limit effort="2.57" lower="-0.2571" upper="0.2971" velocity="1.9"/>
  </joint>
  <link name="HeadPitch_link">
    <inertial>
      <mass value="0.13728"/>
      <inertia ixx="2.23022e-05" ixy="1.3103e-07" ixz="-1.31933e-05" iyy="6.44652e-05" iyz="-4.26e-09" izz="5.78637e-05"/>
      <origin rpy="0 0 0" xyz="0.0014 0 -0.00462"/>
    </inertial>
  </link>
  <joint name="HeadRoll" type="revolute">
    <parent link="HeadPitch_link"/>
    <child link="HeadRoll_link"/>
    <origin rpy="0 0 0" xyz="0 0 0"/>
    <axis xyz="1.0 0 0"/>
    <limit effort="0.9" lower="-0.4887" upper="0.4887" velocity="1.5"/>
  </joint>
  <link name="HeadRoll_link">
    <inertial>
      <mass value="1.79432"/>
      <inertia ixx="0.00808695" ixy="-3.36239e-05" ixz="0.00239535" iyy="0.00960886" iyz="0.000260292" izz="0.00796332"/>
      <origin rpy="0 0 0" xyz="0.01263 0 0.07498"/>
    </inertial>
    <visual>
      <geometry>
        <mesh filename="package://romeo_description/meshes/HeadRoll.dae" scale="1 1 1"/>
      </geometry>
      <origin rpy="0 0 0" xyz="0 0 0"/>
    </visual>
    <collision>
      <geometry>
        <mesh filename="package://romeo_description/meshes/HeadRoll_0.10.stl" scale="1 1 1"/>
      </geometry>
      <origin rpy="0 0 0" xyz="0 0 0"/>
    </collision>
  </link>
  <joint name="gaze_joint" type="fixed">
    <parent link="HeadRoll_link"/>
    <child link="gaze"/>
    <origin rpy="0 0 0" xyz="0.10247 0 0.05425"/>
  </joint>
  <link name="gaze"/>
  <joint name="LHipYaw" type="revolute">
    <parent link="body"/>
    <child link="LHipYaw_link"/>
    <origin rpy="0 0 0" xyz="0.05 0.096 -0.3375"/>
    <axis xyz="0 0 1.0"/>
    <limit effort="25.42" lower="-0.2618" upper="0.2618" velocity="1.045"/>
  </joint>
  <link name="LHipYaw_link">
    <inertial>
      <mass value="0.51527"/>
      <inertia ixx="0.000797373" ixy="-1.0184e-06" ixz="-0.000231697" iyy="0.00131776" iyz="3.91707e-06" izz="0.000785018"/>
      <origin rpy="0 0 0" xyz="-0.00922 -0.00167 0.042"/>
    </inertial>
  </link>
  <joint name="LHipRoll" type="revolute">
    <parent link="LHipYaw_link"/>
    <child link="LHip"/>
    <origin rpy="0 0 0" xyz="0 0 0"/>
    <axis xyz="1.0 0 0"/>
    <limit effort="46.6" lower="-0.2618" upper="0.5236" velocity="2.09"/>
  </joint>
  <link name="LHip">
    <inertial>
      <mass value="0.65864"/>
      <inertia ixx="0.000863659" ixy="-6.20354e-06" ixz="-1.86793e-06" iyy="0.000505068" iyz="1.24373e-06" izz="0.000938555"/>
      <origin rpy="0 0 0" xyz="0.00249 -0.00205 -0.00147"/>
    </inertial>
  </link>
  <joint name="LHipPitch" type="revolute">
    <parent link="LHip"/>
    <child link="LThigh"/>
    <origin rpy="0 0 0" xyz="0 0 0"/>
    <axis xyz="0 1.0 0"/>
    <limit effort="46.6" lower="-1.6581" upper="0.4014" velocity="2.09"/>
  </joint>
  <link name="LThigh">
    <inertial>
      <mass value="4.34097"/>
      <inertia ixx="0.036002" ixy="-2.22796e-05" ixz="0.0230461" iyy="0.0364084" iyz="0.00065633" izz="0.0112971"/>
      <origin rpy="0 0 0" xyz="-0.02138 -0.00255 -0.14577"/>
    </inertial>
    <visual>
      <geometry>
        <mesh filename="package://romeo_description/meshes/LHipPitch.dae" scale="1 1 1"/>
      </geometry>
      <origin rpy="0 0 0" xyz="0 0 0"/>
    </visual>
    <collision>
      <geometry>
        <mesh filename="package://romeo_description/meshes/LHipPitch_0.10.stl" scale="1 1 1"/>
      </geometry>
      <origin rpy="0 0 0" xyz="0 0 0"/>
    </collision>
  </link>
  <joint name="LKneePitch" type="revolute">
    <parent link="LThigh"/>
    <child link="LTibia"/>
    <origin rpy="0 0 0" xyz="0 0 -0.322"/>
    <axis xyz="0 1.0 0"/>
    <limit effort="38.17" lower="-0.0218" upper="1.9722" velocity="6.0"/>
  </joint>
  <link name="LTibia">
    <inertial>
      <mass value="2.50906"/>
      <inertia ixx="0.0146626" ixy="5.06229e-08" ixz="0.00278247" iyy="0.0145661" iyz="-5.66452e-06" izz="0.00340234"/>
      <origin rpy="0 0 0" xyz="-0.00415 -0.00054 -0.11011"/>
    </inertial>
    <visual>
      <geometry>
        <mesh filename="package://romeo_description/meshes/LKneePitch.dae" scale="1 1 1"/>
      </geometry>
      <origin rpy="0 0 0" xyz="0 0 0"/>
    </visual>
    <collision>
      <geometry>
        <mesh filename="package://romeo_description/meshes/LKneePitch_0.10.stl" scale="1 1 1"/>
      </geometry>
      <origin rpy="0 0 0" xyz="0 0 0"/>
    </collision>
  </link>
  <joint name="LAnklePitch" type="revolute">
    <parent link="LTibia"/>
    <child link="LAnklePitch_link"/>
    <origin rpy="0 0 0" xyz="0 0 -0.29"/>
    <axis xyz="0 1.0 0"/>
    <limit effort="25.76" lower="-0.5149" upper="0.7505" velocity="2.1"/>
  </joint>
  <link name="LAnklePitch_link">
    <inertial>
      <mass value="0.42803"/>
      <inertia ixx="0.000338486" ixy="-1.0818e-07" ixz="9.621e-08" iyy="0.000220504" iyz="-1.13514e-06" izz="0.00039211"/>
      <origin rpy="0 0 0" xyz="0.00132 -0.00117 0.00015"/>
    </inertial>
  </link>
  <joint name="LAnkleRoll" type="revolute">
    <parent link="LAnklePitch_link"/>
    <child link="l_ankle"/>
    <origin rpy="0 0 0" xyz="0 0 0"/>
    <axis xyz="1.0 0 0"/>
    <limit effort="25.76" lower="-0.3491" upper="0.3491" velocity="2.1"/>
  </joint>
  <link name="l_ankle">
    <inertial>
      <mass value="0.98379"/>
      <inertia ixx="0.000901343" ixy="-4.5809e-05" ixz="-0.000810091" iyy="0.00540559" iyz="5.65123e-05" izz="0.00543292"/>
      <origin rpy="0 0 0" xyz="0.0483878 0.00120158 -0.0367645"/>
    </inertial>
    <visual>
      <geometry>
        <mesh filename="package://romeo_description/meshes/LAnkleRoll.dae" scale="1 1 1"/>
      </geometry>
      <origin rpy="0 0 0" xyz="0 0 0"/>
    </visual>
    <collision>
      <geometry>
        <mesh filename="package://romeo_description/meshes/LAnkleRoll_0.10.stl" scale="1 1 1"/>
      </geometry>
      <origin rpy="0 0 0" xyz="0 0 0"/>
    </collision>
  </link>
  <joint name="LLeg_effector_fixedjoint" type="fixed">
    <parent link="l_ankle"/>
    <child link="l_sole"/>
    <origin rpy="0 0 0" xyz="0 0 -0.0651"/>
    <axis xyz="0 0 0"/>
  </joint>
  <link name="l_sole"/>
  <joint name="RHipYaw" type="revolute">
    <parent link="body"/>
    <child link="RHipYaw_link"/>
    <origin rpy="0 0 0" xyz="0.05 -0.096 -0.3375"/>
    <axis xyz="0 0 1.0"/>
    <limit effort="25.42" lower="-0.2618" upper="0.2618" velocity="1.045"/>
  </joint>
  <link name="RHipYaw_link">
    <inertial>
      <mass value="0.51527"/>
      <inertia ixx="0.000797373" ixy="-1.6886e-05" ixz="-0.000231697" iyy="0.00131776" iyz="7.61991e-05" izz="0.000785018"/>
      <origin rpy="0 0 0" xyz="-0.00922 0.00167 0.042"/>
    </inertial>
  </link>
  <joint name="RHipRoll" type="revolute">
    <parent link="RHipYaw_link"/>
    <child link="RHip"/>
    <origin rpy="0 0 0" xyz="0 0 0"/>
    <axis xyz="1.0 0 0"/>
    <limit effort="46.6" lower="-0.5236" upper="0.2618" velocity="2.09"/>
  </joint>
  <link name="RHip">
    <inertial>
      <mass value="0.65864"/>
      <inertia ixx="0.000863659" ixy="5.20518e-07" ixz="-1.86793e-06" iyy="0.000505068" iyz="-2.72589e-06" izz="0.000938555"/>
      <origin rpy="0 0 0" xyz="0.00249 0.00205 -0.00147"/>
    </inertial>
  </link>
  <joint name="RHipPitch" type="revolute">
    <parent link="RHip"/>
    <child link="RThigh"/>
    <origin rpy="0 0 0" xyz="0 0 0"/>
    <axis xyz="0 1.0 0"/>
    <limit effort="46.6" lower="-1.6581" upper="0.4014" velocity="2.09"/>
  </joint>
  <link name="RThigh">
    <inertial>
      <mass value="4.34097"/>
      <inertia ixx="0.036002" ixy="-0.00049561" ixz="0.0230461" iyy="0.0364084" iyz="-0.00257086" izz="0.0112971"/>
      <origin rpy="0 0 0" xyz="-0.02138 0.00255 -0.14577"/>
    </inertial>
    <visual>
      <geometry>
        <mesh filename="package://romeo_description/meshes/RHipPitch.dae" scale="1 1 1"/>
      </geometry>
      <origin rpy="0 0 0" xyz="0 0 0"/>
    </visual>
    <collision>
      <geometry>
        <mesh filename="package://romeo_description/meshes/RHipPitch_0.10.stl" scale="1 1 1"/>
      </geometry>
      <origin rpy="0 0 0" xyz="0 0 0"/>
    </collision>
  </link>
  <joint name="RKneePitch" type="revolute">
    <parent link="RThigh"/>
    <child link="RTibia"/>
    <origin rpy="0 0 0" xyz="0 0 -0.322"/>
    <axis xyz="0 1.0 0"/>
    <limit effort="38.17" lower="-0.0218" upper="1.9722" velocity="6.0"/>
  </joint>
  <link name="RTibia">
    <inertial>
      <mass value="2.50906"/>
      <inertia ixx="0.0146626" ixy="-1.1195e-05" ixz="0.00278247" iyy="0.0145661" iyz="-0.000304039" izz="0.00340234"/>
      <origin rpy="0 0 0" xyz="-0.00415 0.00054 -0.11011"/>
    </inertial>
    <visual>
      <geometry>
        <mesh filename="package://romeo_description/meshes/RKneePitch.dae" scale="1 1 1"/>
      </geometry>
      <origin rpy="0 0 0" xyz="0 0 0"/>
    </visual>
    <collision>
      <geometry>
        <mesh filename="package://romeo_description/meshes/RKneePitch_0.10.stl" scale="1 1 1"/>
      </geometry>
      <origin rpy="0 0 0" xyz="0 0 0"/>
    </collision>
  </link>
  <joint name="RAnklePitch" type="revolute">
    <parent link="RTibia"/>
    <child link="RAnklePitch_link"/>
    <origin rpy="0 0 0" xyz="0 0 -0.29"/>
    <axis xyz="0 1.0 0"/>
    <limit effort="25.76" lower="-0.5149" upper="0.7505" velocity="2.1"/>
  </joint>
  <link name="RAnklePitch_link">
    <inertial>
      <mass value="0.42803"/>
      <inertia ixx="0.000338486" ixy="1.21392e-06" ixz="9.621e-08" iyy="0.000220504" iyz="-9.84901e-07" izz="0.00039211"/>
      <origin rpy="0 0 0" xyz="0.00132 0.00117 0.00015"/>
    </inertial>
  </link>
  <joint name="RAnkleRoll" type="revolute">
    <parent link="RAnklePitch_link"/>
    <child link="r_ankle"/>
    <origin rpy="0 0 0" xyz="0 0 0"/>
    <axis xyz="1.0 0 0"/>
    <limit effort="25.76" lower="-0.3491" upper="0.3491" velocity="2.1"/>
  </joint>
  <link name="r_ankle">
    <inertial>
      <mass value="0.98379"/>
      <inertia ixx="0.000901343" ixy="-0.000160208" ixz="-0.000810091" iyy="0.00540559" iyz="0.000143431" izz="0.00543292"/>
      <origin rpy="0 0 0" xyz="0.0483878 -0.00120158 -0.0367645"/>
    </inertial>
    <visual>
      <geometry>
        <mesh filename="package://romeo_description/meshes/RAnkleRoll.dae" scale="1 1 1"/>
      </geometry>
      <origin rpy="0 0 0" xyz="0 0 0"/>
    </visual>
    <collision>
      <geometry>
        <mesh filename="package://romeo_description/meshes/RAnkleRoll_0.10.stl" scale="1 1 1"/>
      </geometry>
      <origin rpy="0 0 0" xyz="0 0 0"/>
    </collision>
  </link>
  <joint name="RLeg_effector_fixedjoint" type="fixed">
    <parent link="r_ankle"/>
    <child link="r_sole"/>
    <origin rpy="0 0 0" xyz="0 0 -0.0651"/>
    <axis xyz="0 0 0"/>
  </joint>
  <link name="r_sole"/>
  <link name="base_link"/>
  <joint name="base_link_fixedjoint" type="fixed">
    <parent link="base_link"/>
    <child link="torso"/>
    <origin rpy="0 0 0" xyz="0 0 0"/>
    <axis xyz="0 0 0"/>
  </joint>
  <link name="torso">
    <inertial>
      <mass value="5.0541"/>
      <inertia ixx="0.0623514" ixy="-3.02711e-06" ixz="0.0093264" iyy="0.0365041" iyz="-0.000132541" izz="0.0639535"/>
      <origin rpy="0 0 0" xyz="0.01512 0 0.06743"/>
    </inertial>
    <visual>
      <geometry>
        <mesh filename="package://romeo_description/meshes/Torso.dae" scale="1 1 1"/>
      </geometry>
      <origin rpy="0 0 0" xyz="0 0 0"/>
    </visual>
    <collision>
      <geometry>
        <mesh filename="package://romeo_description/meshes/Torso_0.10.stl" scale="1 1 1"/>
      </geometry>
      <origin rpy="0 0 0" xyz="0 0 0"/>
    </collision>
  </link>
  <joint name="TrunkYaw" type="revolute">
    <parent link="torso"/>
    <child link="body"/>
    <origin rpy="0 0 0" xyz="0 0 0"/>
    <axis xyz="0 0 1.0"/>
    <limit effort="80.902" lower="-0.7575" upper="0.7575" velocity="1.5"/>
  </joint>
  <link name="body">
    <inertial>
      <mass value="4.4142"/>
      <inertia ixx="0.0487058" ixy="6.27009e-05" ixz="-0.0496477" iyy="0.0449798" iyz="-2.92721e-05" izz="0.0182883"/>
      <origin rpy="0 0 0" xyz="0.02825 0 -0.16653"/>
    </inertial>
    <visual>
      <geometry>
        <mesh filename="package://romeo_description/meshes/TrunkYaw.dae" scale="1 1 1"/>
      </geometry>
      <origin rpy="0 0 0" xyz="0 0 0"/>
    </visual>
    <collision>
      <geometry>
        <mesh filename="package://romeo_description/meshes/TrunkYaw_0.10.stl" scale="1 1 1"/>
      </geometry>
      <origin rpy="0 0 0" xyz="0 0 0"/>
    </collision>
  </link>
  <joint name="LShoulderPitch" type="revolute">
    <parent link="torso"/>
    <child link="LShoulder"/>
    <origin rpy="1.49012e-08 7.45058e-09 0" xyz="0.049862 0.19 0.073851"/>
    <axis xyz="0.417025 0.895055 -0.15801"/>
    <limit effort="19.095" lower="-1.3491" upper="2.2462" velocity="2.2"/>
  </joint>
  <link name="LShoulder">
    <inertial>
      <mass value="0.43527"/>
      <inertia ixx="0.000268738" ixy="-7.98278e-05" ixz="8.02495e-06" iyy="0.000151197" iyz="1.72313e-05" izz="0.000290161"/>
      <origin rpy="0 0 0" xyz="-0.0112798 -0.0260712 0.00468882"/>
    </inertial>
  </link>
  <joint name="LShoulderYaw" type="revolute">
    <parent link="LShoulder"/>
    <child link="LShoulderYaw_link"/>
    <origin rpy="2.98023e-08 1.11759e-08 -5.58793e-08" xyz="0 0 0"/>
    <axis xyz="0.0401398 0.155542 0.987013"/>
    <limit effort="9.031" lower="-0.5768" upper="0.9242" velocity="4.0"/>
  </joint>
  <link name="LShoulderYaw_link">
    <inertial>
      <mass value="0.69262"/>
      <inertia ixx="0.000953111" ixy="0.000479248" ixz="0.000898232" iyy="0.00250956" iyz="-1.65544e-05" izz="0.00233103"/>
      <origin rpy="0 0 0" xyz="0.0965281 0.00465308 0.00168775"/>
    </inertial>
    <visual>
      <geometry>
        <mesh filename="package://romeo_description/meshes/LShoulderYaw.dae" scale="1 1 1"/>
      </geometry>
      <origin rpy="0 0 0" xyz="0 0 0"/>
    </visual>
    <collision>
      <geometry>
        <mesh filename="package://romeo_description/meshes/LShoulderYaw_0.10.stl" scale="1 1 1"/>
      </geometry>
      <origin rpy="0 0 0" xyz="0 0 0"/>
    </collision>
  </link>
  <joint name="LElbowRoll" type="revolute">
    <parent link="LShoulderYaw_link"/>
    <child link="LForeArm"/>
    <origin rpy="-2.56114e-09 0 -9.31322e-09" xyz="0.210824 7.40511e-09 -0.008631"/>
    <axis xyz="0.998889 0.0139984 0.044995"/>
    <limit effort="7.404" lower="-2.2148" upper="1.9042" velocity="3.7"/>
  </joint>
  <link name="LForeArm">
    <inertial>
      <mass value="0.48271"/>
      <inertia ixx="0.000166894" ixy="9.68978e-06" ixz="-1.49781e-05" iyy="0.000408141" iyz="1.2555e-06" izz="0.00036684"/>
      <origin rpy="0 0 0" xyz="-0.0348859 -0.0011589 -0.00148134"/>
    </inertial>
  </link>
  <joint name="LElbowYaw" type="revolute">
    <parent link="LForeArm"/>
    <child link="LElbow"/>
    <origin rpy="-1.49504e-08 -1.86264e-08 2.12577e-09" xyz="0 0 0"/>
    <axis xyz="-0.0449994 0 0.998987"/>
    <limit effort="6.02" lower="-1.5228" upper="0.0044" velocity="4.0"/>
  </joint>
  <link name="LElbow">
    <inertial>
      <mass value="0.36997"/>
      <inertia ixx="0.000404839" ixy="0.000470943" ixz="2.57237e-05" iyy="0.00102723" iyz="2.9528e-05" izz="0.000987329"/>
      <origin rpy="0 0 0" xyz="0.068523 0.0097 0.00458766"/>
    </inertial>
    <visual>
      <geometry>
        <mesh filename="package://romeo_description/meshes/LElbowYaw.dae" scale="1 1 1"/>
      </geometry>
      <origin rpy="0 0 0" xyz="0 0 0"/>
    </visual>
    <collision>
      <geometry>
        <mesh filename="package://romeo_description/meshes/LElbowYaw_0.10.stl" scale="1 1 1"/>
      </geometry>
      <origin rpy="0 0 0" xyz="0 0 0"/>
    </collision>
  </link>
  <joint name="LWristRoll" type="revolute">
    <parent link="LElbow"/>
    <child link="LWristRoll_link"/>
    <origin rpy="0 -7.45058e-09 0" xyz="0.190404 0 0.008631"/>
    <axis xyz="0.998987 0 0.0449994"/>
    <limit effort="2.177" lower="-3.6303" upper="0.4887" velocity="1.1"/>
  </joint>
  <link name="LWristRoll_link">
    <inertial>
      <mass value="0.17551"/>
      <inertia ixx="8.1046e-05" ixy="-1.46219e-06" ixz="-3.67139e-05" iyy="0.000308979" iyz="-8.92509e-08" izz="0.000294305"/>
      <origin rpy="0 0 0" xyz="-0.0592449 6e-05 -0.00144745"/>
    </inertial>
    <visual>
      <geometry>
        <mesh filename="package://romeo_description/meshes/LWristRoll.dae" scale="1 1 1"/>
      </geometry>
      <origin rpy="0 0 0" xyz="0 0 0"/>
    </visual>
    <collision>
      <geometry>
        <mesh filename="package://romeo_description/meshes/LWristRoll_0.10.stl" scale="1 1 1"/>
      </geometry>
      <origin rpy="0 0 0" xyz="0 0 0"/>
    </collision>
  </link>
  <joint name="LWristYaw" type="revolute">
    <parent link="LWristRoll_link"/>
    <child link="LWristYaw_link"/>
    <origin rpy="0 0 0" xyz="0 0 0"/>
    <axis xyz="-0.0449994 0 0.998987"/>
    <limit effort="0.862" lower="-0.4014" upper="0.4014" velocity="2.26"/>
  </joint>
  <link name="LWristYaw_link">
    <inertial>
      <mass value="0.061"/>
      <inertia ixx="1.25161e-05" ixy="-4.16668e-08" ixz="-7.01768e-07" iyy="2.83374e-05" iyz="1.56375e-08" izz="2.79694e-05"/>
      <origin rpy="0 0 0" xyz="-0.00657144 0.00017 -0.000115829"/>
    </inertial>
    <visual>
      <geometry>
        <mesh filename="package://romeo_description/meshes/LWristYaw.dae" scale="1 1 1"/>
      </geometry>
      <origin rpy="0 0 0" xyz="0 0 0"/>
    </visual>
    <collision>
      <geometry>
        <mesh filename="package://romeo_description/meshes/LWristYaw_0.10.stl" scale="1 1 1"/>
      </geometry>
      <origin rpy="0 0 0" xyz="0 0 0"/>
    </collision>
  </link>
  <joint name="LWristPitch" type="revolute">
    <parent link="LWristYaw_link"/>
    <child link="l_wrist"/>
    <origin rpy="0 0 0" xyz="0 0 0"/>
    <axis xyz="0 1.0 0"/>
    <limit effort="0.6" lower="-0.988" upper="0.8969" velocity="3.75"/>
  </joint>
  <link name="l_wrist">
    <inertial>
      <mass value="0.35549"/>
      <inertia ixx="0.000325271" ixy="-0.000324985" ixz="1.52493e-05" iyy="0.000666741" iyz="6.27901e-05" izz="0.000820118"/>
      <origin rpy="0 0 0" xyz="0.07358 -0.00628 -0.00098"/>
    </inertial>
    <visual>
      <geometry>
        <mesh filename="package://romeo_description/meshes/LWristPitch.dae" scale="1 1 1"/>
      </geometry>
      <origin rpy="0 0 0" xyz="0 0 0"/>
    </visual>
    <collision>
      <geometry>
        <mesh filename="package://romeo_description/meshes/LWristPitch_0.10.stl" scale="1 1 1"/>
      </geometry>
      <origin rpy="0 0 0" xyz="0 0 0"/>
    </collision>
  </link>
  <joint name="LHand" type="revolute">
    <parent link="l_wrist"/>
    <child link="l_gripper"/>
    <origin rpy="1.5708 0.0450146 -3.14159" xyz="-0.0579412 -0.0159 -0.00260997"/>
    <axis xyz="1.0 0 0"/>
    <limit effort="0.649997" lower="0" upper="1.0" velocity="59.8925"/>
  </joint>
  <link name="l_gripper"/>
  <joint name="RShoulderPitch" type="revolute">
    <parent link="torso"/>
    <child link="RShoulder"/>
    <origin rpy="-1.49012e-08 7.45058e-09 0" xyz="0.049862 -0.19 0.073851"/>
    <axis xyz="-0.417025 0.895055 0.15801"/>
    <limit effort="19.095" lower="-1.4554" upper="2.1399" velocity="2.2"/>
  </joint>
  <link name="RShoulder">
    <inertial>
      <mass value="0.43527"/>
      <inertia ixx="0.000264235" ixy="8.24341e-05" ixz="1.55448e-05" iyy="0.000160752" iyz="-3.06968e-05" izz="0.000285109"/>
      <origin rpy="0 0 0" xyz="-0.0112798 0.0260712 0.00468882"/>
    </inertial>
  </link>
  <joint name="RShoulderYaw" type="revolute">
    <parent link="RShoulder"/>
    <child link="RShoulderYaw_link"/>
    <origin rpy="-2.98023e-08 1.49012e-08 -6.42613e-08" xyz="0 0 0"/>
    <axis xyz="0.0401398 -0.155542 0.987014"/>
    <limit effort="9.031" lower="-1.0985" upper="0.4025" velocity="4.0"/>
  </joint>
  <link name="RShoulderYaw_link">
    <inertial>
      <mass value="0.69262"/>
      <inertia ixx="0.000955527" ixy="-0.000291705" ixz="0.000927729" iyy="0.00250758" iyz="1.49948e-05" izz="0.00233059"/>
      <origin rpy="0 0 0" xyz="0.0965281 -0.00465308 0.00168775"/>
    </inertial>
    <visual>
      <geometry>
        <mesh filename="package://romeo_description/meshes/RShoulderYaw.dae" scale="1 1 1"/>
      </geometry>
      <origin rpy="0 0 0" xyz="0 0 0"/>
    </visual>
    <collision>
      <geometry>
        <mesh filename="package://romeo_description/meshes/RShoulderYaw_0.10.stl" scale="1 1 1"/>
      </geometry>
      <origin rpy="0 0 0" xyz="0 0 0"/>
    </collision>
  </link>
  <joint name="RElbowRoll" type="revolute">
    <parent link="RShoulderYaw_link"/>
    <child link="RForeArm"/>
    <origin rpy="6.69388e-09 7.45058e-09 -7.91624e-08" xyz="0.210824 -1.48548e-08 -0.008631"/>
    <axis xyz="0.998889 -0.0139984 0.044995"/>
    <limit effort="7.404" lower="-1.9047" upper="2.2143" velocity="3.7"/>
  </joint>
  <link name="RForeArm">
    <inertial>
      <mass value="0.48271"/>
      <inertia ixx="0.000166993" ixy="-6.12728e-06" ixz="-1.49476e-05" iyy="0.000408038" iyz="7.67117e-07" izz="0.000366843"/>
      <origin rpy="0 0 0" xyz="-0.0348859 0.0011589 -0.00148134"/>
    </inertial>
  </link>
  <joint name="RElbowYaw" type="revolute">
    <parent link="RForeArm"/>
    <child link="RElbow"/>
    <origin rpy="1.49504e-08 -1.86264e-08 -2.12577e-09" xyz="0 0 0"/>
    <axis xyz="-0.0449994 0 0.998987"/>
    <limit effort="6.02" lower="-0.0047" upper="1.5225" velocity="4.0"/>
  </joint>
  <link name="RElbow">
    <inertial>
      <mass value="0.36997"/>
      <inertia ixx="0.000404839" ixy="-2.08748e-05" ixz="2.57237e-05" iyy="0.00102723" iyz="-3.39957e-06" izz="0.000987329"/>
      <origin rpy="0 0 0" xyz="0.068523 -0.0097 0.00458766"/>
    </inertial>
    <visual>
      <geometry>
        <mesh filename="package://romeo_description/meshes/RElbowYaw.dae" scale="1 1 1"/>
      </geometry>
      <origin rpy="0 0 0" xyz="0 0 0"/>
    </visual>
    <collision>
      <geometry>
        <mesh filename="package://romeo_description/meshes/RElbowYaw_0.10.stl" scale="1 1 1"/>
      </geometry>
      <origin rpy="0 0 0" xyz="0 0 0"/>
    </collision>
  </link>
  <joint name="RWristRoll" type="revolute">
    <parent link="RElbow"/>
    <child link="RWristRoll_link"/>
    <origin rpy="0 -7.45058e-09 0" xyz="0.190404 0 0.008631"/>
    <axis xyz="0.998987 0 0.0449994"/>
    <limit effort="2.177" lower="-0.4887" upper="3.6303" velocity="1.1"/>
  </joint>
  <link name="RWristRoll_link">
    <inertial>
      <mass value="0.17551"/>
      <inertia ixx="8.1046e-05" ixy="-2.14425e-07" ixz="-3.67139e-05" iyy="0.000308979" iyz="-5.87658e-08" izz="0.000294305"/>
      <origin rpy="0 0 0" xyz="-0.0592449 -6e-05 -0.00144745"/>
    </inertial>
    <visual>
      <geometry>
        <mesh filename="package://romeo_description/meshes/RWristRoll.dae" scale="1 1 1"/>
      </geometry>
      <origin rpy="0 0 0" xyz="0 0 0"/>
    </visual>
    <collision>
      <geometry>
        <mesh filename="package://romeo_description/meshes/RWristRoll_0.10.stl" scale="1 1 1"/>
      </geometry>
      <origin rpy="0 0 0" xyz="0 0 0"/>
    </collision>
  </link>
  <joint name="RWristYaw" type="revolute">
    <parent link="RWristRoll_link"/>
    <child link="RWristYaw_link"/>
    <origin rpy="0 0 0" xyz="0 0 0"/>
    <axis xyz="-0.0449994 0 0.998987"/>
    <limit effort="0.862" lower="-0.4014" upper="0.4014" velocity="2.26"/>
  </joint>
  <link name="RWristYaw_link">
    <inertial>
      <mass value="0.061"/>
      <inertia ixx="1.25161e-05" ixy="9.4625e-08" ixz="-7.01768e-07" iyy="2.83374e-05" iyz="1.80397e-08" izz="2.79694e-05"/>
      <origin rpy="0 0 0" xyz="-0.00657144 -0.00017 -0.000115829"/>
    </inertial>
    <visual>
      <geometry>
        <mesh filename="package://romeo_description/meshes/RWristYaw.dae" scale="1 1 1"/>
      </geometry>
      <origin rpy="0 0 0" xyz="0 0 0"/>
    </visual>
    <collision>
      <geometry>
        <mesh filename="package://romeo_description/meshes/RWristYaw_0.10.stl" scale="1 1 1"/>
      </geometry>
      <origin rpy="0 0 0" xyz="0 0 0"/>
    </collision>
  </link>
  <joint name="RWristPitch" type="revolute">
    <parent link="RWristYaw_link"/>
    <child link="r_wrist"/>
    <origin rpy="0 0 0" xyz="0 0 0"/>
    <axis xyz="0 1.0 0"/>
    <limit effort="0.6" lower="-0.9868" upper="0.8981" velocity="3.75"/>
  </joint>
  <link name="r_wrist">
    <inertial>
      <mass value="0.35549"/>
      <inertia ixx="0.000325271" ixy="3.54589e-06" ixz="1.52493e-05" iyy="0.000666741" iyz="5.84145e-05" izz="0.000820118"/>
      <origin rpy="0 0 0" xyz="0.07358 0.00628 -0.00098"/>
    </inertial>
    <visual>
      <geometry>
        <mesh filename="package://romeo_description/meshes/RWristPitch.dae" scale="1 1 1"/>
      </geometry>
      <origin rpy="0 0 0" xyz="0 0 0"/>
    </visual>
    <collision>
      <geometry>
        <mesh filename="package://romeo_description/meshes/RWristPitch_0.10.stl" scale="1 1 1"/>
      </geometry>
      <origin rpy="0 0 0" xyz="0 0 0"/>
    </collision>
  </link>
  <joint name="RHand" type="revolute">
    <parent link="r_wrist"/>
    <child link="r_gripper"/>
    <origin rpy="1.5708 0.0450146 -3.14159" xyz="-0.0579412 -0.0159 -0.00260997"/>
    <axis xyz="1.0 0 0"/>
    <limit effort="0.649997" lower="0" upper="1.0" velocity="59.8925"/>
  </joint>
  <link name="r_gripper"/>
  <joint name="LEyeYaw" type="revolute">
    <parent link="HeadRoll_link"/>
    <child link="LEyeYaw_link"/>
    <origin rpy="0 0 0" xyz="0.08948 0.03192 0.05425"/>
    <axis xyz="0 0 1.0"/>
    <limit effort="0.01752" lower="-0.523599" upper="0.523599" velocity="293.215"/>
  </joint>
  <link name="LEyeYaw_link">
    <inertial>
      <mass value="0.01"/>
      <inertia ixx="0" ixy="0" ixz="0" iyy="0" iyz="0" izz="0"/>
      <origin rpy="0 0 0" xyz="0 0 0"/>
    </inertial>
  </link>
  <joint name="LEyePitch" type="revolute">
    <parent link="LEyeYaw_link"/>
    <child link="LEye"/>
    <origin rpy="0 0 0" xyz="0 0 0"/>
    <axis xyz="0 1.0 0"/>
    <limit effort="0.01752" lower="-0.349066" upper="0.349066" velocity="293.215"/>
  </joint>
  <link name="LEye">
    <inertial>
      <mass value="0.01"/>
      <inertia ixx="0" ixy="0" ixz="0" iyy="0" iyz="0" izz="0"/>
      <origin rpy="0 0 0" xyz="0 0 0"/>
    </inertial>
    <visual>
      <geometry>
        <mesh filename="package://romeo_description/meshes/LEyePitch.dae" scale="1 1 1"/>
      </geometry>
      <origin rpy="0 0 0" xyz="0 0 0"/>
    </visual>
    <collision>
      <geometry>
        <mesh filename="package://romeo_description/meshes/LEyePitch_0.10.stl" scale="1 1 1"/>
      </geometry>
      <origin rpy="0 0 0" xyz="0 0 0"/>
    </collision>
  </link>
  <joint name="REyeYaw" type="revolute">
    <parent link="HeadRoll_link"/>
    <child link="REyeYaw_link"/>
    <origin rpy="0 0 0" xyz="0.08948 -0.03192 0.05425"/>
    <axis xyz="0 0 1.0"/>
    <limit effort="0.01752" lower="-0.523599" upper="0.523599" velocity="293.215"/>
  </joint>
  <link name="REyeYaw_link">
    <inertial>
      <mass value="0.01"/>
      <inertia ixx="0" ixy="0" ixz="0" iyy="0" iyz="0" izz="0"/>
      <origin rpy="0 0 0" xyz="0 0 0"/>
    </inertial>
  </link>
  <joint name="REyePitch" type="revolute">
    <parent link="REyeYaw_link"/>
    <child link="REye"/>
    <origin rpy="0 0 0" xyz="0 0 0"/>
    <axis xyz="0 1.0 0"/>
    <limit effort="0.01752" lower="-0.349066" upper="0.349066" velocity="293.215"/>
  </joint>
  <link name="REye">
    <inertial>
      <mass value="0.01"/>
      <inertia ixx="0" ixy="0" ixz="0" iyy="0" iyz="0" izz="0"/>
      <origin rpy="0 0 0" xyz="0 0 0"/>
    </inertial>
    <visual>
      <geometry>
        <mesh filename="package://romeo_description/meshes/REyePitch.dae" scale="1 1 1"/>
      </geometry>
      <origin rpy="0 0 0" xyz="0 0 0"/>
    </visual>
    <collision>
      <geometry>
        <mesh filename="package://romeo_description/meshes/REyePitch_0.10.stl" scale="1 1 1"/>
      </geometry>
      <origin rpy="0 0 0" xyz="0 0 0"/>
    </collision>
  </link>
  <link name="RFsrFToeRearRight_frame"/>
  <joint name="RFoot/FSR/ToeRearRight_sensor_fixedjoint" type="fixed">
    <parent link="r_ankle"/>
    <child link="RFsrFToeRearRight_frame"/>
    <origin rpy="0 0 0" xyz="0.11898 -0.0335 -0.06226"/>
    <axis xyz="0 0 0"/>
  </joint>
  <link name="CameraLeftEye_frame"/>
  <joint name="CameraLeftEye_sensor_fixedjoint" type="fixed">
    <parent link="LEye"/>
    <child link="CameraLeftEye_frame"/>
    <origin rpy="0 0 0" xyz="0.01299 0 0"/>
    <axis xyz="0 0 0"/>
  </joint>
  <link name="ImuHeadGyrometer_frame"/>
  <joint name="GyrometerHead_sensor_fixedjoint" type="fixed">
    <parent link="HeadRoll_link"/>
    <child link="ImuHeadGyrometer_frame"/>
    <origin rpy="0 0 1.5708" xyz="-0.01135 -0.04225 0.16011"/>
    <axis xyz="0 0 0"/>
  </joint>
  <link name="RFsrRearCenter_frame"/>
  <joint name="RFoot/FSR/CenterRear_sensor_fixedjoint" type="fixed">
    <parent link="r_ankle"/>
    <child link="RFsrRearCenter_frame"/>
    <origin rpy="0 0 0" xyz="0.01448 -0.0145 -0.06226"/>
    <axis xyz="0 0 0"/>
  </joint>
  <link name="RFsrFrontCenter_frame"/>
  <joint name="RFoot/FSR/CenterFront_sensor_fixedjoint" type="fixed">
    <parent link="r_ankle"/>
    <child link="RFsrFrontCenter_frame"/>
    <origin rpy="0 0 0" xyz="0.07498 -0.01275 -0.06226"/>
    <axis xyz="0 0 0"/>
  </joint>
  <link name="LFsrHeelRight_frame"/>
  <joint name="LFoot/FSR/HeelRight_sensor_fixedjoint" type="fixed">
    <parent link="l_ankle"/>
    <child link="LFsrHeelRight_frame"/>
    <origin rpy="0 0 0" xyz="-0.04602 -0.017 -0.06226"/>
    <axis xyz="0 0 0"/>
  </joint>
  <link name="CameraRightEye_frame"/>
  <joint name="CameraRightEye_sensor_fixedjoint" type="fixed">
    <parent link="REye"/>
    <child link="CameraRightEye_frame"/>
    <origin rpy="0 0 0" xyz="0.01299 0 0"/>
    <axis xyz="0 0 0"/>
  </joint>
  <link name="RFsrFToeFrontRight_frame"/>
  <joint name="RFoot/FSR/ToeFrontRight_sensor_fixedjoint" type="fixed">
    <parent link="r_ankle"/>
    <child link="RFsrFToeFrontRight_frame"/>
    <origin rpy="0 0 0" xyz="0.16098 -0.024 -0.06226"/>
    <axis xyz="0 0 0"/>
  </joint>
  <link name="RFsrHeelRight_frame"/>
  <joint name="RFoot/FSR/HeelRight_sensor_fixedjoint" type="fixed">
    <parent link="r_ankle"/>
    <child link="RFsrHeelRight_frame"/>
    <origin rpy="0 0 0" xyz="-0.04602 -0.017 -0.06226"/>
    <axis xyz="0 0 0"/>
  </joint>
  <link name="RFsrFToeRearLeft_frame"/>
  <joint name="RFoot/FSR/ToeRearLeft_sensor_fixedjoint" type="fixed">
    <parent link="r_ankle"/>
    <child link="RFsrFToeRearLeft_frame"/>
    <origin rpy="0 0 0" xyz="0.12698 0.0315 -0.06226"/>
    <axis xyz="0 0 0"/>
  </joint>
  <link name="ImuTorsoAccelerometer_frame"/>
  <joint name="AccelerometerDownTorso_sensor_fixedjoint" type="fixed">
    <parent link="body"/>
    <child link="ImuTorsoAccelerometer_frame"/>
    <origin rpy="0 0 0" xyz="0.06185 0.0087 -0.1582"/>
    <axis xyz="0 0 0"/>
  </joint>
  <link name="LFsrFToeRearRight_frame"/>
  <joint name="LFoot/FSR/ToeRearRight_sensor_fixedjoint" type="fixed">
    <parent link="l_ankle"/>
    <child link="LFsrFToeRearRight_frame"/>
    <origin rpy="0 0 0" xyz="0.12698 -0.0315 -0.06226"/>
    <axis xyz="0 0 0"/>
  </joint>
  <link name="LFsrHeelLeft_frame"/>
  <joint name="LFoot/FSR/HeelLeft_sensor_fixedjoint" type="fixed">
    <parent link="l_ankle"/>
    <child link="LFsrHeelLeft_frame"/>
    <origin rpy="0 0 0" xyz="-0.04602 0.017 -0.06226"/>
    <axis xyz="0 0 0"/>
  </joint>
  <link name="CameraRight_frame"/>
  <joint name="CameraRight_sensor_fixedjoint" type="fixed">
    <parent link="HeadRoll_link"/>
    <child link="CameraRight_frame"/>
    <origin rpy="0 0 0" xyz="0.11229 -0.04 0.09938"/>
    <axis xyz="0 0 0"/>
  </joint>
  <link name="ImuTorsoGyrometer_frame"/>
  <joint name="GyrometerDownTorso_sensor_fixedjoint" type="fixed">
    <parent link="body"/>
    <child link="ImuTorsoGyrometer_frame"/>
    <origin rpy="0 0 0" xyz="0.06185 0.0087 -0.1582"/>
    <axis xyz="0 0 0"/>
  </joint>
  <link name="LFsrFToeRearLeft_frame"/>
  <joint name="LFoot/FSR/ToeRearLeft_sensor_fixedjoint" type="fixed">
    <parent link="l_ankle"/>
    <child link="LFsrFToeRearLeft_frame"/>
    <origin rpy="0 0 0" xyz="0.11898 0.0335 -0.06226"/>
    <axis xyz="0 0 0"/>
  </joint>
  <link name="LFsrRearCenter_frame"/>
  <joint name="LFoot/FSR/CenterRear_sensor_fixedjoint" type="fixed">
    <parent link="l_ankle"/>
    <child link="LFsrRearCenter_frame"/>
    <origin rpy="0 0 0" xyz="0.01448 0.0145 -0.06226"/>
    <axis xyz="0 0 0"/>
  </joint>
  <link name="CameraLeft_frame"/>
  <joint name="CameraLeft_sensor_fixedjoint" type="fixed">
    <parent link="HeadRoll_link"/>
    <child link="CameraLeft_frame"/>
    <origin rpy="0 0 0" xyz="0.11229 0.04 0.09938"/>
    <axis xyz="0 0 0"/>
  </joint>
  <link name="LFsrFToeFrontRight_frame"/>
  <joint name="LFoot/FSR/ToeFrontRight_sensor_fixedjoint" type="fixed">
    <parent link="l_ankle"/>
    <child link="LFsrFToeFrontRight_frame"/>
    <origin rpy="0 0 0" xyz="0.17298 -0.023 -0.06226"/>
    <axis xyz="0 0 0"/>
  </joint>
  <link name="RFsrHeelLeft_frame"/>
  <joint name="RFoot/FSR/HeelLeft_sensor_fixedjoint" type="fixed">
    <parent link="r_ankle"/>
    <child link="RFsrHeelLeft_frame"/>
    <origin rpy="0 0 0" xyz="-0.04602 0.017 -0.06226"/>
    <axis xyz="0 0 0"/>
  </joint>
  <link name="ImuHeadAccelerometer_frame"/>
  <joint name="AccelerometerHead_sensor_fixedjoint" type="fixed">
    <parent link="HeadRoll_link"/>
    <child link="ImuHeadAccelerometer_frame"/>
    <origin rpy="0 0 1.5708" xyz="-0.01135 -0.04225 0.16011"/>
    <axis xyz="0 0 0"/>
  </joint>
  <link name="LFsrFrontCenter_frame"/>
  <joint name="LFoot/FSR/CenterFront_sensor_fixedjoint" type="fixed">
    <parent link="l_ankle"/>
    <child link="LFsrFrontCenter_frame"/>
    <origin rpy="0 0 0" xyz="0.07498 0.01275 -0.06226"/>
    <axis xyz="0 0 0"/>
  </joint>
  <link name="RFsrFToeFrontLeft_frame"/>
  <joint name="RFoot/FSR/ToeFrontLeft_sensor_fixedjoint" type="fixed">
    <parent link="r_ankle"/>
    <child link="RFsrFToeFrontLeft_frame"/>
    <origin rpy="0 0 0" xyz="0.17298 0.023 -0.06226"/>
    <axis xyz="0 0 0"/>
  </joint>
  <link name="LFsrFToeFrontLeft_frame"/>
  <joint name="LFoot/FSR/ToeFrontLeft_sensor_fixedjoint" type="fixed">
    <parent link="l_ankle"/>
    <child link="LFsrFToeFrontLeft_frame"/>
    <origin rpy="0 0 0" xyz="0.16098 0.024 -0.06226"/>
    <axis xyz="0 0 0"/>
  </joint>
  <link name="RFinger13_link">
    <visual>
      <geometry>
        <mesh filename="package://romeo_description/meshes/RFinger13.dae" scale="1 1 1"/>
      </geometry>
      <origin rpy="0 0 0" xyz="0 0 0"/>
    </visual>
    <collision>
      <geometry>
        <mesh filename="package://romeo_description/meshes/RFinger13_0.10.stl" scale="1 1 1"/>
      </geometry>
      <origin rpy="0 0 0" xyz="0 0 0"/>
    </collision>
  </link>
  <joint name="RFinger13" type="continuous">
    <parent link="RFinger12_link"/>
    <child link="RFinger13_link"/>
    <origin rpy="0 0 0" xyz="0 0.0230916 -5.90086e-06"/>
    <axis xyz="0 0 1.0"/>
    <mimic joint="RHand" multiplier="0.988205" offset="0"/>
  </joint>
  <link name="RFinger12_link">
    <visual>
      <geometry>
        <mesh filename="package://romeo_description/meshes/RFinger12.dae" scale="1 1 1"/>
      </geometry>
      <origin rpy="0 0 0" xyz="0 0 0"/>
    </visual>
    <collision>
      <geometry>
        <mesh filename="package://romeo_description/meshes/RFinger12_0.10.stl" scale="1 1 1"/>
      </geometry>
      <origin rpy="0 0 0" xyz="0 0 0"/>
    </collision>
  </link>
  <joint name="RFinger12" type="continuous">
    <parent link="RFinger11_link"/>
    <child link="RFinger12_link"/>
    <origin rpy="0 0 0" xyz="0 0.0230929 4.02331e-06"/>
    <axis xyz="0 0 1.0"/>
    <mimic joint="RHand" multiplier="0.988205" offset="0"/>
  </joint>
  <link name="LFinger33_link">
    <visual>
      <geometry>
        <mesh filename="package://romeo_description/meshes/LFinger33.dae" scale="1 1 1"/>
      </geometry>
      <origin rpy="0 0 0" xyz="0 0 0"/>
    </visual>
    <collision>
      <geometry>
        <mesh filename="package://romeo_description/meshes/LFinger33_0.10.stl" scale="1 1 1"/>
      </geometry>
      <origin rpy="0 0 0" xyz="0 0 0"/>
    </collision>
  </link>
  <joint name="LFinger33" type="continuous">
    <parent link="LFinger32_link"/>
    <child link="LFinger33_link"/>
    <origin rpy="0 0 0" xyz="0 0.0230916 -5.91576e-06"/>
    <axis xyz="0 0 1.0"/>
    <mimic joint="LHand" multiplier="0.988205" offset="0"/>
  </joint>
  <link name="RFinger31_link">
    <visual>
      <geometry>
        <mesh filename="package://romeo_description/meshes/RFinger31.dae" scale="1 1 1"/>
      </geometry>
      <origin rpy="0 0 0" xyz="0 0 0"/>
    </visual>
    <collision>
      <geometry>
        <mesh filename="package://romeo_description/meshes/RFinger31_0.10.stl" scale="1 1 1"/>
      </geometry>
      <origin rpy="0 0 0" xyz="0 0 0"/>
    </collision>
  </link>
  <joint name="RFinger31" type="continuous">
    <parent link="r_wrist"/>
    <child link="RFinger31_link"/>
    <origin rpy="1.69304 1.5708 3.14159" xyz="0.11215 -0.03024 0.00999"/>
    <axis xyz="0 0 1.0"/>
    <mimic joint="RHand" multiplier="0.988205" offset="0"/>
  </joint>
  <link name="RFinger32_link">
    <visual>
      <geometry>
        <mesh filename="package://romeo_description/meshes/RFinger32.dae" scale="1 1 1"/>
      </geometry>
      <origin rpy="0 0 0" xyz="0 0 0"/>
    </visual>
    <collision>
      <geometry>
        <mesh filename="package://romeo_description/meshes/RFinger32_0.10.stl" scale="1 1 1"/>
      </geometry>
      <origin rpy="0 0 0" xyz="0 0 0"/>
    </collision>
  </link>
  <joint name="RFinger32" type="continuous">
    <parent link="RFinger31_link"/>
    <child link="RFinger32_link"/>
    <origin rpy="0 0 0" xyz="0 -0.0230929 -4.02331e-06"/>
    <axis xyz="0 0 1.0"/>
    <mimic joint="RHand" multiplier="0.988205" offset="0"/>
  </joint>
  <link name="LFinger21_link">
    <visual>
      <geometry>
        <mesh filename="package://romeo_description/meshes/LFinger21.dae" scale="1 1 1"/>
      </geometry>
      <origin rpy="0 0 0" xyz="0 0 0"/>
    </visual>
    <collision>
      <geometry>
        <mesh filename="package://romeo_description/meshes/LFinger21_0.10.stl" scale="1 1 1"/>
      </geometry>
      <origin rpy="0 0 0" xyz="0 0 0"/>
    </collision>
  </link>
  <joint name="LFinger21" type="continuous">
    <parent link="l_wrist"/>
    <child link="LFinger21_link"/>
    <origin rpy="1.5708 1.5708 3.14159" xyz="0.12934 0 0.01499"/>
    <axis xyz="0 0 1.0"/>
    <mimic joint="LHand" multiplier="0.988205" offset="0"/>
  </joint>
  <link name="LFinger13_link">
    <visual>
      <geometry>
        <mesh filename="package://romeo_description/meshes/LFinger13.dae" scale="1 1 1"/>
      </geometry>
      <origin rpy="0 0 0" xyz="0 0 0"/>
    </visual>
    <collision>
      <geometry>
        <mesh filename="package://romeo_description/meshes/LFinger13_0.10.stl" scale="1 1 1"/>
      </geometry>
      <origin rpy="0 0 0" xyz="0 0 0"/>
    </collision>
  </link>
  <joint name="LFinger13" type="continuous">
    <parent link="LFinger12_link"/>
    <child link="LFinger13_link"/>
    <origin rpy="0 0 0" xyz="0 -0.0230916 5.90086e-06"/>
    <axis xyz="0 0 1.0"/>
    <mimic joint="LHand" multiplier="0.988205" offset="0"/>
  </joint>
  <link name="LFinger32_link">
    <visual>
      <geometry>
        <mesh filename="package://romeo_description/meshes/LFinger32.dae" scale="1 1 1"/>
      </geometry>
      <origin rpy="0 0 0" xyz="0 0 0"/>
    </visual>
    <collision>
      <geometry>
        <mesh filename="package://romeo_description/meshes/LFinger32_0.10.stl" scale="1 1 1"/>
      </geometry>
      <origin rpy="0 0 0" xyz="0 0 0"/>
    </collision>
  </link>
  <joint name="LFinger32" type="continuous">
    <parent link="LFinger31_link"/>
    <child link="LFinger32_link"/>
    <origin rpy="0 0 0" xyz="0 0.0230928 4.02331e-06"/>
    <axis xyz="0 0 1.0"/>
    <mimic joint="LHand" multiplier="0.988205" offset="0"/>
  </joint>
  <link name="LFinger11_link">
    <visual>
      <geometry>
        <mesh filename="package://romeo_description/meshes/LFinger11.dae" scale="1 1 1"/>
      </geometry>
      <origin rpy="0 0 0" xyz="0 0 0"/>
    </visual>
    <collision>
      <geometry>
        <mesh filename="package://romeo_description/meshes/LFinger11_0.10.stl" scale="1 1 1"/>
      </geometry>
      <origin rpy="0 0 0" xyz="0 0 0"/>
    </collision>
  </link>
  <joint name="LFinger11" type="continuous">
    <parent link="l_wrist"/>
    <child link="LFinger11_link"/>
    <origin rpy="1.69304 1.5708 3.14159" xyz="0.12385 -0.03024 0.00999"/>
    <axis xyz="0 0 1.0"/>
    <mimic joint="LHand" multiplier="0.988205" offset="0"/>
  </joint>
  <link name="RFinger22_link">
    <visual>
      <geometry>
        <mesh filename="package://romeo_description/meshes/RFinger22.dae" scale="1 1 1"/>
      </geometry>
      <origin rpy="0 0 0" xyz="0 0 0"/>
    </visual>
    <collision>
      <geometry>
        <mesh filename="package://romeo_description/meshes/RFinger22_0.10.stl" scale="1 1 1"/>
      </geometry>
      <origin rpy="0 0 0" xyz="0 0 0"/>
    </collision>
  </link>
  <joint name="RFinger22" type="continuous">
    <parent link="RFinger21_link"/>
    <child link="RFinger22_link"/>
    <origin rpy="0 0 0" xyz="0 0.02309 0"/>
    <axis xyz="0 0 1.0"/>
    <mimic joint="RHand" multiplier="0.988205" offset="0"/>
  </joint>
  <link name="LFinger22_link">
    <visual>
      <geometry>
        <mesh filename="package://romeo_description/meshes/LFinger22.dae" scale="1 1 1"/>
      </geometry>
      <origin rpy="0 0 0" xyz="0 0 0"/>
    </visual>
    <collision>
      <geometry>
        <mesh filename="package://romeo_description/meshes/LFinger22_0.10.stl" scale="1 1 1"/>
      </geometry>
      <origin rpy="0 0 0" xyz="0 0 0"/>
    </collision>
  </link>
  <joint name="LFinger22" type="continuous">
    <parent link="LFinger21_link"/>
    <child link="LFinger22_link"/>
    <origin rpy="0 0 0" xyz="0 -0.02309 0"/>
    <axis xyz="0 0 1.0"/>
    <mimic joint="LHand" multiplier="0.988205" offset="0"/>
  </joint>
  <link name="RFinger21_link">
    <visual>
      <geometry>
        <mesh filename="package://romeo_description/meshes/RFinger21.dae" scale="1 1 1"/>
      </geometry>
      <origin rpy="0 0 0" xyz="0 0 0"/>
    </visual>
    <collision>
      <geometry>
        <mesh filename="package://romeo_description/meshes/RFinger21_0.10.stl" scale="1 1 1"/>
      </geometry>
      <origin rpy="0 0 0" xyz="0 0 0"/>
    </collision>
  </link>
  <joint name="RFinger21" type="continuous">
    <parent link="r_wrist"/>
    <child link="RFinger21_link"/>
    <origin rpy="1.5708 -1.5708 -3.14159" xyz="0.12934 0 0.01499"/>
    <axis xyz="0 0 1.0"/>
    <mimic joint="RHand" multiplier="0.988205" offset="0"/>
  </joint>
  <link name="LFinger12_link">
    <visual>
      <geometry>
        <mesh filename="package://romeo_description/meshes/LFinger12.dae" scale="1 1 1"/>
      </geometry>
      <origin rpy="0 0 0" xyz="0 0 0"/>
    </visual>
    <collision>
      <geometry>
        <mesh filename="package://romeo_description/meshes/LFinger12_0.10.stl" scale="1 1 1"/>
      </geometry>
      <origin rpy="0 0 0" xyz="0 0 0"/>
    </collision>
  </link>
  <joint name="LFinger12" type="continuous">
    <parent link="LFinger11_link"/>
    <child link="LFinger12_link"/>
    <origin rpy="0 0 0" xyz="0 -0.0230929 -4.02331e-06"/>
    <axis xyz="0 0 1.0"/>
    <mimic joint="LHand" multiplier="0.988205" offset="0"/>
  </joint>
  <link name="RFinger23_link">
    <visual>
      <geometry>
        <mesh filename="package://romeo_description/meshes/RFinger23.dae" scale="1 1 1"/>
      </geometry>
      <origin rpy="0 0 0" xyz="0 0 0"/>
    </visual>
    <collision>
      <geometry>
        <mesh filename="package://romeo_description/meshes/RFinger23_0.10.stl" scale="1 1 1"/>
      </geometry>
      <origin rpy="0 0 0" xyz="0 0 0"/>
    </collision>
  </link>
  <joint name="RFinger23" type="continuous">
    <parent link="RFinger22_link"/>
    <child link="RFinger23_link"/>
    <origin rpy="0 0 0" xyz="0 0.02309 0"/>
    <axis xyz="0 0 1.0"/>
    <mimic joint="RHand" multiplier="0.988205" offset="0"/>
  </joint>
  <link name="RFinger11_link">
    <visual>
      <geometry>
        <mesh filename="package://romeo_description/meshes/RFinger11.dae" scale="1 1 1"/>
      </geometry>
      <origin rpy="0 0 0" xyz="0 0 0"/>
    </visual>
    <collision>
      <geometry>
        <mesh filename="package://romeo_description/meshes/RFinger11_0.10.stl" scale="1 1 1"/>
      </geometry>
      <origin rpy="0 0 0" xyz="0 0 0"/>
    </collision>
  </link>
  <joint name="RFinger11" type="continuous">
    <parent link="r_wrist"/>
    <child link="RFinger11_link"/>
    <origin rpy="1.69304 -1.5708 3.14159" xyz="0.12385 0.03024 0.00999"/>
    <axis xyz="0 0 1.0"/>
    <mimic joint="RHand" multiplier="0.988205" offset="0"/>
  </joint>
  <link name="LFinger23_link">
    <visual>
      <geometry>
        <mesh filename="package://romeo_description/meshes/LFinger23.dae" scale="1 1 1"/>
      </geometry>
      <origin rpy="0 0 0" xyz="0 0 0"/>
    </visual>
    <collision>
      <geometry>
        <mesh filename="package://romeo_description/meshes/LFinger23_0.10.stl" scale="1 1 1"/>
      </geometry>
      <origin rpy="0 0 0" xyz="0 0 0"/>
    </collision>
  </link>
  <joint name="LFinger23" type="continuous">
    <parent link="LFinger22_link"/>
    <child link="LFinger23_link"/>
    <origin rpy="0 0 0" xyz="0 -0.02309 0"/>
    <axis xyz="0 0 1.0"/>
    <mimic joint="LHand" multiplier="0.988205" offset="0"/>
  </joint>
  <link name="LFinger31_link">
    <visual>
      <geometry>
        <mesh filename="package://romeo_description/meshes/LFinger31.dae" scale="1 1 1"/>
      </geometry>
      <origin rpy="0 0 0" xyz="0 0 0"/>
    </visual>
    <collision>
      <geometry>
        <mesh filename="package://romeo_description/meshes/LFinger31_0.10.stl" scale="1 1 1"/>
      </geometry>
      <origin rpy="0 0 0" xyz="0 0 0"/>
    </collision>
  </link>
  <joint name="LFinger31" type="continuous">
    <parent link="l_wrist"/>
    <child link="LFinger31_link"/>
    <origin rpy="1.69304 -1.5708 3.14159" xyz="0.11215 0.03024 0.00999"/>
    <axis xyz="0 0 1.0"/>
    <mimic joint="LHand" multiplier="0.988205" offset="0"/>
  </joint>
  <link name="RFinger33_link">
    <visual>
      <geometry>
        <mesh filename="package://romeo_description/meshes/RFinger33.dae" scale="1 1 1"/>
      </geometry>
      <origin rpy="0 0 0" xyz="0 0 0"/>
    </visual>
    <collision>
      <geometry>
        <mesh filename="package://romeo_description/meshes/RFinger33_0.10.stl" scale="1 1 1"/>
      </geometry>
      <origin rpy="0 0 0" xyz="0 0 0"/>
    </collision>
  </link>
  <joint name="RFinger33" type="continuous">
    <parent link="RFinger32_link"/>
    <child link="RFinger33_link"/>
    <origin rpy="0 0 0" xyz="0 -0.0230916 5.90086e-06"/>
    <axis xyz="0 0 1.0"/>
    <mimic joint="RHand" multiplier="0.988205" offset="0"/>
  </joint>
  <link name="LThumb3_link">
    <visual>
      <geometry>
        <mesh filename="package://romeo_description/meshes/LThumb3.dae" scale="1 1 1"/>
      </geometry>
      <origin rpy="0 0 0" xyz="0 0 0"/>
    </visual>
    <collision>
      <geometry>
        <mesh filename="package://romeo_description/meshes/LThumb3_0.10.stl" scale="1 1 1"/>
      </geometry>
      <origin rpy="0 0 0" xyz="0 0 0"/>
    </collision>
  </link>
  <joint name="LThumb3" type="continuous">
    <parent link="LThumb2_link"/>
    <child link="LThumb3_link"/>
    <origin rpy="-5.96047e-08 0 1.49012e-08" xyz="0.0187362 0.0135152 5.21541e-06"/>
    <axis xyz="0 0 1.0"/>
    <mimic joint="LHand" multiplier="0.988205" offset="0"/>
  </joint>
  <link name="LThumb1_link">
    <visual>
      <geometry>
        <mesh filename="package://romeo_description/meshes/LThumb1.dae" scale="1 1 1"/>
      </geometry>
      <origin rpy="0 0 0" xyz="0 0 0"/>
    </visual>
    <collision>
      <geometry>
        <mesh filename="package://romeo_description/meshes/LThumb1_0.10.stl" scale="1 1 1"/>
      </geometry>
      <origin rpy="0 0 0" xyz="0 0 0"/>
    </collision>
  </link>
  <joint name="LThumb1" type="continuous">
    <parent link="l_wrist"/>
    <child link="LThumb1_link"/>
    <origin rpy="-2.97779 1.21665 -3.14159" xyz="0.0624 -0.03131 -0.00574"/>
    <axis xyz="0 0 1.0"/>
    <mimic joint="LHand" multiplier="1.74533" offset="0"/>
  </joint>
  <link name="RThumb1_link">
    <visual>
      <geometry>
        <mesh filename="package://romeo_description/meshes/RThumb1.dae" scale="1 1 1"/>
      </geometry>
      <origin rpy="0 0 0" xyz="0 0 0"/>
    </visual>
    <collision>
      <geometry>
        <mesh filename="package://romeo_description/meshes/RThumb1_0.10.stl" scale="1 1 1"/>
      </geometry>
      <origin rpy="0 0 0" xyz="0 0 0"/>
    </collision>
  </link>
  <joint name="RThumb1" type="continuous">
    <parent link="r_wrist"/>
    <child link="RThumb1_link"/>
    <origin rpy="0.1638 -1.21665 0" xyz="0.0624 0.03131 -0.00574"/>
    <axis xyz="0 0 1.0"/>
    <mimic joint="RHand" multiplier="1.74533" offset="0"/>
  </joint>
  <link name="RThumb2_link">
    <visual>
      <geometry>
        <mesh filename="package://romeo_description/meshes/RThumb2.dae" scale="1 1 1"/>
      </geometry>
      <origin rpy="0 0 0" xyz="0 0 0"/>
    </visual>
    <collision>
      <geometry>
        <mesh filename="package://romeo_description/meshes/RThumb2_0.10.stl" scale="1 1 1"/>
      </geometry>
      <origin rpy="0 0 0" xyz="0 0 0"/>
    </collision>
  </link>
  <joint name="RThumb2" type="continuous">
    <parent link="RThumb1_link"/>
    <child link="RThumb2_link"/>
    <origin rpy="1.13316 0 -1.80698" xyz="-0.000329241 0.0388865 -0.017011"/>
    <axis xyz="0 0 1.0"/>
    <mimic joint="RHand" multiplier="0.988205" offset="0"/>
  </joint>
  <link name="LThumb2_link">
    <visual>
      <geometry>
        <mesh filename="package://romeo_description/meshes/LThumb2.dae" scale="1 1 1"/>
      </geometry>
      <origin rpy="0 0 0" xyz="0 0 0"/>
    </visual>
    <collision>
      <geometry>
        <mesh filename="package://romeo_description/meshes/LThumb2_0.10.stl" scale="1 1 1"/>
      </geometry>
      <origin rpy="0 0 0" xyz="0 0 0"/>
    </collision>
  </link>
  <joint name="LThumb2" type="continuous">
    <parent link="LThumb1_link"/>
    <child link="LThumb2_link"/>
    <origin rpy="1.13316 7.45058e-09 -1.80698" xyz="0.000329241 -0.0388865 0.017011"/>
    <axis xyz="0 0 1.0"/>
    <mimic joint="LHand" multiplier="0.988205" offset="0"/>
  </joint>
  <link name="RThumb3_link">
    <visual>
      <geometry>
        <mesh filename="package://romeo_description/meshes/RThumb3.dae" scale="1 1 1"/>
      </geometry>
      <origin rpy="0 0 0" xyz="0 0 0"/>
    </visual>
    <collision>
      <geometry>
        <mesh filename="package://romeo_description/meshes/RThumb3_0.10.stl" scale="1 1 1"/>
      </geometry>
      <origin rpy="0 0 0" xyz="0 0 0"/>
    </collision>
  </link>
  <joint name="RThumb3" type="continuous">
    <parent link="RThumb2_link"/>
    <child link="RThumb3_link"/>
    <origin rpy="-5.96047e-08 -1.49012e-08 1.49012e-08" xyz="-0.0187362 -0.0135152 -5.21541e-06"/>
    <axis xyz="0 0 1.0"/>
    <mimic joint="RHand" multiplier="0.988205" offset="0"/>
  </joint>
  <link name="CameraDepth_frame"/>
  <joint name="CameraDepth_joint" type="fixed">
    <parent link="HeadRoll_link"/>
    <child link="CameraDepth_frame"/>
    <origin rpy="2.0043951 0 1.57079632679" xyz="0.1403 -0.04708 0.14655"/>
  </joint>
  <link name="Cap">
    <inertial>
      <mass value="0.29923"/>
      <inertia ixx="0.000412832" ixy="-1.67846e-06" ixz="0.000111721" iyy="0.000383921" iyz="5.04259e-05" izz="0.000264006"/>
      <origin rpy="0 0 0" xyz="0 0 0"/>
    </inertial>
    <visual>
      <geometry>
        <mesh filename="package://romeo_description/meshes/Cap.dae" scale="1 1 1"/>
      </geometry>
      <origin rpy="0 0 0" xyz="0 0 0"/>
    </visual>
  </link>
  <joint name="Cap_joint" type="fixed">
    <parent link="HeadRoll_link"/>
    <child link="Cap"/>
    <origin rpy="0 0 0" xyz="0 0 0"/>
  </joint>
</robot>

